<?xml version="1.0"?>
<robot name="Holybro_X500_V2">

  <!-- Base Link -->
  <link name="base_link">
    <inertial>
      <mass value="1.692"/> <!-- Mass in kg -->
      
      <!-- Inertia in kg·m² (replace with actual values from Fusion 360 or CAD tool) -->
      <inertia ixx="0.04304" ixy="7.835E-05" ixz="-5.077E-05"
               iyy="0.04288" iyz="3.879E-06" izz="0.06955"/>
    </inertial>

    <visual>
      <geometry>
        <cylinder radius="0.2" length="0.05"/>
      </geometry>
      <material>
        <ambient>0 0.6 1 1</ambient>
        <diffuse>0 0.6 1 1</diffuse>
      </material>
    </visual>

    <collision>
      <geometry>
        <cylinder radius="0.2" length="0.05"/>
      </geometry>
    </collision>

  </link>

  <!-- Center of Mass -->
  <gazebo reference="base_link">
    <center_of_mass>0.002531 -0.000142 -0.022411</center_of_mass> <!-- CoM in meters -->
  </gazebo>

  <!-- Front Left Rotor -->
  <joint name="rotor_front_left_joint" type="revolute">
    <parent link="base_link"/>
    <child link="rotor_front_left"/>
    <axis xyz="0 0 1"/>
    <limit effort="1.0" velocity="10.0"/>
  </joint>

  <link name="rotor_front_left">
    <visual>
      <geometry>
        <cylinder radius="0.15" length="0.02"/> <!-- Adjusted dimensions for the rotor -->
      </geometry>
      <material>
        <ambient>1 0 0 1</ambient> <!-- Red rotor -->
        <diffuse>1 0 0 1</diffuse>
      </material>
    </visual>
  </link>

  <!-- Front Right Rotor -->
  <joint name="rotor_front_right_joint" type="revolute">
    <parent link="base_link"/>
    <child link="rotor_front_right"/>
    <axis xyz="0 0 1"/>
    <limit effort="1.0" velocity="10.0"/>
  </joint>

  <link name="rotor_front_right">
    <visual>
      <geometry>
        <cylinder radius="0.15" length="0.02"/>
      </geometry>
      <material>
        <ambient>0 1 0 1</ambient> <!-- Green rotor -->
        <diffuse>0 1 0 1</diffuse>
      </material>
    </visual>
  </link>

  <!-- Rear Left Rotor -->
  <joint name="rotor_rear_left_joint" type="revolute">
    <parent link="base_link"/>
    <child link="rotor_rear_left"/>
    <axis xyz="0 0 1"/>
    <limit effort="1.0" velocity="10.0"/>
  </joint>

  <link name="rotor_rear_left">
    <visual>
      <geometry>
        <cylinder radius="0.15" length="0.02"/>
      </geometry>
      <material>
        <ambient>0 0 1 1</ambient> <!-- Blue rotor -->
        <diffuse>0 0 1 1</diffuse>
      </material>
    </visual>
  </link>

  <!-- Rear Right Rotor -->
  <joint name="rotor_rear_right_joint" type="revolute">
    <parent link="base_link"/>
    <child link="rotor_rear_right"/>
    <axis xyz="0 0 1"/>
    <limit effort="1.0" velocity="10.0"/>
  </joint>

  <link name="rotor_rear_right">
    <visual>
      <geometry>
        <cylinder radius="0.15" length="0.02"/>
      </geometry>
      <material>
        <ambient>1 1 0 1</ambient> <!-- Yellow rotor -->
        <diffuse>1 1 0 1</diffuse>
      </material>
    </visual>
  </link>

</robot>
